self=$$;  ( mysqldump --single-transaction --quick --lock-tables=false -u _363fe932c43ad783 -p********** _363fe932c43ad783 -h 127.0.0.1 -P 3306   || kill $self )  | /usr/bin/gzip >> ./deepak.com/private/backups/20221123_180012-deepak_com-database.sql.gz

Backup Summary for deepak.com at 2022-11-23 18:00:17.734270
Config  : ./deepak.com/private/backups/20221123_180012-deepak_com-site_config_backup.json 161.0B
Database: ./deepak.com/private/backups/20221123_180012-deepak_com-database.sql.gz         594.0KiB
Backup for Site deepak.com has been successfully completed
self=$$;  ( mysqldump --single-transaction --quick --lock-tables=false -u _363fe932c43ad783 -p********** _363fe932c43ad783 -h 127.0.0.1 -P 3306   || kill $self )  | /usr/bin/gzip >> ./deepak.com/private/backups/20221124_000014-deepak_com-database.sql.gz

Backup Summary for deepak.com at 2022-11-24 00:00:27.622245
Config  : ./deepak.com/private/backups/20221124_000014-deepak_com-site_config_backup.json 161.0B
Database: ./deepak.com/private/backups/20221124_000014-deepak_com-database.sql.gz         4.7MiB
Backup for Site deepak.com has been successfully completed
Backup failed for Site deepak.com. Database or site_config.json may be corrupted
Traceback (most recent call last):
  File "env/lib/python3.10/site-packages/pymysql/connections.py", line 613, in connect
    sock = socket.create_connection(
  File "/usr/lib/python3.10/socket.py", line 845, in create_connection
    raise err
  File "/usr/lib/python3.10/socket.py", line 833, in create_connection
    sock.connect(sa)
ConnectionRefusedError: [Errno 111] Connection refused

During handling of the above exception, another exception occurred:

Traceback (most recent call last):
  File "apps/frappe/frappe/commands/site.py", line 714, in backup
    odb = scheduled_backup(
  File "apps/frappe/frappe/utils/backups.py", line 532, in scheduled_backup
    odb = new_backup(
  File "apps/frappe/frappe/utils/backups.py", line 566, in new_backup
    odb = BackupGenerator(
  File "apps/frappe/frappe/utils/backups.py", line 84, in __init__
    self.setup_backup_tables()
  File "apps/frappe/frappe/utils/backups.py", line 116, in setup_backup_tables
    existing_tables = frappe.db.get_tables()
  File "apps/frappe/frappe/database/mariadb/database.py", line 426, in get_tables
    frappe.qb.from_(information_schema.tables)
  File "apps/frappe/frappe/query_builder/utils.py", line 86, in execute_query
    return frappe.db.sql(query, params, *args, **kwargs)  # nosemgrep
  File "apps/frappe/frappe/database/database.py", line 200, in sql
    self.connect()
  File "apps/frappe/frappe/database/database.py", line 114, in connect
    self._conn = self.get_connection()
  File "apps/frappe/frappe/database/mariadb/database.py", line 98, in get_connection
    conn = self._get_connection()
  File "apps/frappe/frappe/database/mariadb/database.py", line 104, in _get_connection
    return self.create_connection()
  File "apps/frappe/frappe/database/mariadb/database.py", line 107, in create_connection
    return pymysql.connect(**self.get_connection_settings())
  File "env/lib/python3.10/site-packages/pymysql/connections.py", line 353, in __init__
    self.connect()
  File "env/lib/python3.10/site-packages/pymysql/connections.py", line 664, in connect
    raise exc
pymysql.err.OperationalError: (2003, "Can't connect to MySQL server on '127.0.0.1' ([Errno 111] Connection refused)")

